2025-06-21 08:17:24,884 INFO    MainThread:2917 [wandb_setup.py:_flush():76] Current SDK version is 0.15.3
2025-06-21 08:17:24,884 INFO    MainThread:2917 [wandb_setup.py:_flush():76] Configure stats pid to 2917
2025-06-21 08:17:24,884 INFO    MainThread:2917 [wandb_setup.py:_flush():76] Loading settings from /root/.config/wandb/settings
2025-06-21 08:17:24,884 INFO    MainThread:2917 [wandb_setup.py:_flush():76] Loading settings from /yinyongjing/SMDM/wandb/settings
2025-06-21 08:17:24,884 INFO    MainThread:2917 [wandb_setup.py:_flush():76] Loading settings from environment variables: {'api_key': '***REDACTED***', 'mode': 'online'}
2025-06-21 08:17:24,884 INFO    MainThread:2917 [wandb_setup.py:_flush():76] Applying setup settings: {'_disable_service': False}
2025-06-21 08:17:24,884 INFO    MainThread:2917 [wandb_setup.py:_flush():76] Inferring run settings from compute environment: {'program_relpath': 'pretrain/train_mdm.py', 'program': '/yinyongjing/SMDM/pretrain/train_mdm.py'}
2025-06-21 08:17:24,885 INFO    MainThread:2917 [wandb_init.py:_log_setup():507] Logging user logs to workdir/scaling_debug/mdm-170M-10.0/wandb/run-20250621_081724-cyzwissj/logs/debug.log
2025-06-21 08:17:24,885 INFO    MainThread:2917 [wandb_init.py:_log_setup():508] Logging internal logs to workdir/scaling_debug/mdm-170M-10.0/wandb/run-20250621_081724-cyzwissj/logs/debug-internal.log
2025-06-21 08:17:24,885 INFO    MainThread:2917 [wandb_init.py:init():547] calling init triggers
2025-06-21 08:17:24,885 INFO    MainThread:2917 [wandb_init.py:init():554] wandb.init called with sweep_config: {}
config: {}
2025-06-21 08:17:24,886 INFO    MainThread:2917 [wandb_init.py:init():596] starting backend
2025-06-21 08:17:24,886 INFO    MainThread:2917 [wandb_init.py:init():600] setting up manager
2025-06-21 08:17:24,896 INFO    MainThread:2917 [backend.py:_multiprocessing_setup():106] multiprocessing start_methods=fork,spawn,forkserver, using: spawn
2025-06-21 08:17:24,903 INFO    MainThread:2917 [wandb_init.py:init():606] backend started and connected
2025-06-21 08:17:24,913 INFO    MainThread:2917 [wandb_init.py:init():700] updated telemetry
2025-06-21 08:17:25,072 INFO    MainThread:2917 [wandb_init.py:init():737] communicating run to backend with 60.0 second timeout
2025-06-21 08:17:52,991 INFO    Thread-3  :2917 [retry.py:__call__():172] Retry attempt failed:
Traceback (most recent call last):
  File "/yinyongjing/anaconda3/envs/smdm/lib/python3.9/site-packages/urllib3/connection.py", line 174, in _new_conn
    conn = connection.create_connection(
  File "/yinyongjing/anaconda3/envs/smdm/lib/python3.9/site-packages/urllib3/util/connection.py", line 95, in create_connection
    raise err
  File "/yinyongjing/anaconda3/envs/smdm/lib/python3.9/site-packages/urllib3/util/connection.py", line 85, in create_connection
    sock.connect(sa)
socket.timeout: timed out

During handling of the above exception, another exception occurred:

Traceback (most recent call last):
  File "/yinyongjing/anaconda3/envs/smdm/lib/python3.9/site-packages/urllib3/connectionpool.py", line 716, in urlopen
    httplib_response = self._make_request(
  File "/yinyongjing/anaconda3/envs/smdm/lib/python3.9/site-packages/urllib3/connectionpool.py", line 404, in _make_request
    self._validate_conn(conn)
  File "/yinyongjing/anaconda3/envs/smdm/lib/python3.9/site-packages/urllib3/connectionpool.py", line 1061, in _validate_conn
    conn.connect()
  File "/yinyongjing/anaconda3/envs/smdm/lib/python3.9/site-packages/urllib3/connection.py", line 363, in connect
    self.sock = conn = self._new_conn()
  File "/yinyongjing/anaconda3/envs/smdm/lib/python3.9/site-packages/urllib3/connection.py", line 179, in _new_conn
    raise ConnectTimeoutError(
urllib3.exceptions.ConnectTimeoutError: (<urllib3.connection.HTTPSConnection object at 0x7fc6559c4a30>, 'Connection to api.wandb.ai timed out. (connect timeout=10)')

During handling of the above exception, another exception occurred:

Traceback (most recent call last):
  File "/yinyongjing/anaconda3/envs/smdm/lib/python3.9/site-packages/requests/adapters.py", line 667, in send
    resp = conn.urlopen(
  File "/yinyongjing/anaconda3/envs/smdm/lib/python3.9/site-packages/urllib3/connectionpool.py", line 802, in urlopen
    retries = retries.increment(
  File "/yinyongjing/anaconda3/envs/smdm/lib/python3.9/site-packages/urllib3/util/retry.py", line 594, in increment
    raise MaxRetryError(_pool, url, error or ResponseError(cause))
urllib3.exceptions.MaxRetryError: HTTPSConnectionPool(host='api.wandb.ai', port=443): Max retries exceeded with url: /graphql (Caused by ConnectTimeoutError(<urllib3.connection.HTTPSConnection object at 0x7fc6559c4a30>, 'Connection to api.wandb.ai timed out. (connect timeout=10)'))

During handling of the above exception, another exception occurred:

Traceback (most recent call last):
  File "/yinyongjing/anaconda3/envs/smdm/lib/python3.9/site-packages/wandb/sdk/lib/retry.py", line 131, in __call__
    result = self._call_fn(*args, **kwargs)
  File "/yinyongjing/anaconda3/envs/smdm/lib/python3.9/site-packages/wandb/sdk/internal/internal_api.py", line 285, in execute
    return self.client.execute(*args, **kwargs)  # type: ignore
  File "/yinyongjing/anaconda3/envs/smdm/lib/python3.9/site-packages/wandb/vendor/gql-0.2.0/wandb_gql/client.py", line 52, in execute
    result = self._get_result(document, *args, **kwargs)
  File "/yinyongjing/anaconda3/envs/smdm/lib/python3.9/site-packages/wandb/vendor/gql-0.2.0/wandb_gql/client.py", line 60, in _get_result
    return self.transport.execute(document, *args, **kwargs)
  File "/yinyongjing/anaconda3/envs/smdm/lib/python3.9/site-packages/wandb/sdk/lib/gql_request.py", line 55, in execute
    request = self.session.post(self.url, **post_args)
  File "/yinyongjing/anaconda3/envs/smdm/lib/python3.9/site-packages/requests/sessions.py", line 637, in post
    return self.request("POST", url, data=data, json=json, **kwargs)
  File "/yinyongjing/anaconda3/envs/smdm/lib/python3.9/site-packages/requests/sessions.py", line 589, in request
    resp = self.send(prep, **send_kwargs)
  File "/yinyongjing/anaconda3/envs/smdm/lib/python3.9/site-packages/requests/sessions.py", line 703, in send
    r = adapter.send(request, **kwargs)
  File "/yinyongjing/anaconda3/envs/smdm/lib/python3.9/site-packages/requests/adapters.py", line 688, in send
    raise ConnectTimeout(e, request=request)
requests.exceptions.ConnectTimeout: HTTPSConnectionPool(host='api.wandb.ai', port=443): Max retries exceeded with url: /graphql (Caused by ConnectTimeoutError(<urllib3.connection.HTTPSConnection object at 0x7fc6559c4a30>, 'Connection to api.wandb.ai timed out. (connect timeout=10)'))
2025-06-21 08:18:25,096 ERROR   MainThread:2917 [wandb_init.py:init():763] encountered error: Run initialization has timed out after 60.0 sec. 
Please refer to the documentation for additional information: https://docs.wandb.ai/guides/track/tracking-faq#initstarterror-error-communicating-with-wandb-process-
2025-06-21 08:18:26,333 ERROR   MainThread:2917 [wandb_init.py:init():1168] Run initialization has timed out after 60.0 sec. 
Please refer to the documentation for additional information: https://docs.wandb.ai/guides/track/tracking-faq#initstarterror-error-communicating-with-wandb-process-
Traceback (most recent call last):
  File "/yinyongjing/anaconda3/envs/smdm/lib/python3.9/site-packages/wandb/sdk/wandb_init.py", line 1150, in init
    run = wi.init()
  File "/yinyongjing/anaconda3/envs/smdm/lib/python3.9/site-packages/wandb/sdk/wandb_init.py", line 769, in init
    raise error
wandb.errors.CommError: Run initialization has timed out after 60.0 sec. 
Please refer to the documentation for additional information: https://docs.wandb.ai/guides/track/tracking-faq#initstarterror-error-communicating-with-wandb-process-
2025-06-21 08:18:31,645 WARNING MsgRouterThr:2917 [router.py:message_loop():77] message_loop has been closed
