2025-06-21 08:17:24,918 INFO    StreamThr :3540 [internal.py:wandb_internal():86] W&B internal server running at pid: 3540, started at: 2025-06-21 08:17:24.916655
2025-06-21 08:17:24,921 DEBUG   HandlerThread:3540 [handler.py:handle_request():144] handle_request: status
2025-06-21 08:17:24,925 INFO    WriterThread:3540 [datastore.py:open_for_write():85] open: workdir/scaling_debug/mdm-170M-10.0/wandb/run-20250621_081724-cyzwissj/run-cyzwissj.wandb
2025-06-21 08:17:24,927 DEBUG   SenderThread:3540 [sender.py:send():375] send: header
2025-06-21 08:17:25,073 DEBUG   SenderThread:3540 [sender.py:send():375] send: run
2025-06-21 08:17:25,078 INFO    SenderThread:3540 [sender.py:_maybe_setup_resume():761] checking resume status for None/scaling/cyzwissj
2025-06-21 08:17:30,076 DEBUG   HandlerThread:3540 [handler.py:handle_request():144] handle_request: keepalive
2025-06-21 08:17:35,077 DEBUG   HandlerThread:3540 [handler.py:handle_request():144] handle_request: keepalive
2025-06-21 08:17:40,079 DEBUG   HandlerThread:3540 [handler.py:handle_request():144] handle_request: keepalive
2025-06-21 08:17:45,082 DEBUG   HandlerThread:3540 [handler.py:handle_request():144] handle_request: keepalive
2025-06-21 08:17:50,083 DEBUG   HandlerThread:3540 [handler.py:handle_request():144] handle_request: keepalive
2025-06-21 08:17:55,085 DEBUG   HandlerThread:3540 [handler.py:handle_request():144] handle_request: keepalive
2025-06-21 08:17:58,498 INFO    SenderThread:3540 [retry.py:__call__():172] Retry attempt failed:
Traceback (most recent call last):
  File "/yinyongjing/anaconda3/envs/smdm/lib/python3.9/site-packages/urllib3/connection.py", line 174, in _new_conn
    conn = connection.create_connection(
  File "/yinyongjing/anaconda3/envs/smdm/lib/python3.9/site-packages/urllib3/util/connection.py", line 95, in create_connection
    raise err
  File "/yinyongjing/anaconda3/envs/smdm/lib/python3.9/site-packages/urllib3/util/connection.py", line 85, in create_connection
    sock.connect(sa)
socket.timeout: timed out

During handling of the above exception, another exception occurred:

Traceback (most recent call last):
  File "/yinyongjing/anaconda3/envs/smdm/lib/python3.9/site-packages/urllib3/connectionpool.py", line 716, in urlopen
    httplib_response = self._make_request(
  File "/yinyongjing/anaconda3/envs/smdm/lib/python3.9/site-packages/urllib3/connectionpool.py", line 404, in _make_request
    self._validate_conn(conn)
  File "/yinyongjing/anaconda3/envs/smdm/lib/python3.9/site-packages/urllib3/connectionpool.py", line 1061, in _validate_conn
    conn.connect()
  File "/yinyongjing/anaconda3/envs/smdm/lib/python3.9/site-packages/urllib3/connection.py", line 363, in connect
    self.sock = conn = self._new_conn()
  File "/yinyongjing/anaconda3/envs/smdm/lib/python3.9/site-packages/urllib3/connection.py", line 179, in _new_conn
    raise ConnectTimeoutError(
urllib3.exceptions.ConnectTimeoutError: (<urllib3.connection.HTTPSConnection object at 0x7fc86dbe77f0>, 'Connection to api.wandb.ai timed out. (connect timeout=10)')

During handling of the above exception, another exception occurred:

Traceback (most recent call last):
  File "/yinyongjing/anaconda3/envs/smdm/lib/python3.9/site-packages/requests/adapters.py", line 667, in send
    resp = conn.urlopen(
  File "/yinyongjing/anaconda3/envs/smdm/lib/python3.9/site-packages/urllib3/connectionpool.py", line 802, in urlopen
    retries = retries.increment(
  File "/yinyongjing/anaconda3/envs/smdm/lib/python3.9/site-packages/urllib3/util/retry.py", line 594, in increment
    raise MaxRetryError(_pool, url, error or ResponseError(cause))
urllib3.exceptions.MaxRetryError: HTTPSConnectionPool(host='api.wandb.ai', port=443): Max retries exceeded with url: /graphql (Caused by ConnectTimeoutError(<urllib3.connection.HTTPSConnection object at 0x7fc86dbe77f0>, 'Connection to api.wandb.ai timed out. (connect timeout=10)'))

During handling of the above exception, another exception occurred:

Traceback (most recent call last):
  File "/yinyongjing/anaconda3/envs/smdm/lib/python3.9/site-packages/wandb/sdk/lib/retry.py", line 131, in __call__
    result = self._call_fn(*args, **kwargs)
  File "/yinyongjing/anaconda3/envs/smdm/lib/python3.9/site-packages/wandb/sdk/internal/internal_api.py", line 285, in execute
    return self.client.execute(*args, **kwargs)  # type: ignore
  File "/yinyongjing/anaconda3/envs/smdm/lib/python3.9/site-packages/wandb/vendor/gql-0.2.0/wandb_gql/client.py", line 52, in execute
    result = self._get_result(document, *args, **kwargs)
  File "/yinyongjing/anaconda3/envs/smdm/lib/python3.9/site-packages/wandb/vendor/gql-0.2.0/wandb_gql/client.py", line 60, in _get_result
    return self.transport.execute(document, *args, **kwargs)
  File "/yinyongjing/anaconda3/envs/smdm/lib/python3.9/site-packages/wandb/sdk/lib/gql_request.py", line 55, in execute
    request = self.session.post(self.url, **post_args)
  File "/yinyongjing/anaconda3/envs/smdm/lib/python3.9/site-packages/requests/sessions.py", line 637, in post
    return self.request("POST", url, data=data, json=json, **kwargs)
  File "/yinyongjing/anaconda3/envs/smdm/lib/python3.9/site-packages/requests/sessions.py", line 589, in request
    resp = self.send(prep, **send_kwargs)
  File "/yinyongjing/anaconda3/envs/smdm/lib/python3.9/site-packages/requests/sessions.py", line 703, in send
    r = adapter.send(request, **kwargs)
  File "/yinyongjing/anaconda3/envs/smdm/lib/python3.9/site-packages/requests/adapters.py", line 688, in send
    raise ConnectTimeout(e, request=request)
requests.exceptions.ConnectTimeout: HTTPSConnectionPool(host='api.wandb.ai', port=443): Max retries exceeded with url: /graphql (Caused by ConnectTimeoutError(<urllib3.connection.HTTPSConnection object at 0x7fc86dbe77f0>, 'Connection to api.wandb.ai timed out. (connect timeout=10)'))
2025-06-21 08:18:00,086 DEBUG   HandlerThread:3540 [handler.py:handle_request():144] handle_request: keepalive
2025-06-21 08:18:05,088 DEBUG   HandlerThread:3540 [handler.py:handle_request():144] handle_request: keepalive
2025-06-21 08:18:10,090 DEBUG   HandlerThread:3540 [handler.py:handle_request():144] handle_request: keepalive
2025-06-21 08:18:15,092 DEBUG   HandlerThread:3540 [handler.py:handle_request():144] handle_request: keepalive
2025-06-21 08:18:20,094 DEBUG   HandlerThread:3540 [handler.py:handle_request():144] handle_request: keepalive
2025-06-21 08:18:25,097 DEBUG   HandlerThread:3540 [handler.py:handle_request():144] handle_request: cancel
2025-06-21 08:18:25,097 DEBUG   HandlerThread:3540 [handler.py:handle_request():144] handle_request: cancel
2025-06-21 08:18:26,362 DEBUG   HandlerThread:3540 [handler.py:handle_request():144] handle_request: shutdown
2025-06-21 08:18:26,362 INFO    HandlerThread:3540 [handler.py:finish():842] shutting down handler
2025-06-21 08:18:27,097 INFO    WriterThread:3540 [datastore.py:close():298] close: workdir/scaling_debug/mdm-170M-10.0/wandb/run-20250621_081724-cyzwissj/run-cyzwissj.wandb
2025-06-21 08:18:31,643 DEBUG   SenderThread:3540 [sender.py:send():384] Record cancelled: run
2025-06-21 08:18:31,643 INFO    SenderThread:3540 [sender.py:finish():1550] shutting down sender
