2025-06-21 07:19:16,739 INFO    StreamThr :3560 [internal.py:wandb_internal():86] W&B internal server running at pid: 3560, started at: 2025-06-21 07:19:16.738266
2025-06-21 07:19:16,742 DEBUG   HandlerThread:3560 [handler.py:handle_request():144] handle_request: status
2025-06-21 07:19:16,744 INFO    WriterThread:3560 [datastore.py:open_for_write():85] open: workdir/scaling_debug/mdm-170M-10.0/wandb/run-20250621_071916-2gnbqjsi/run-2gnbqjsi.wandb
2025-06-21 07:19:16,751 DEBUG   SenderThread:3560 [sender.py:send():375] send: header
2025-06-21 07:19:16,980 DEBUG   SenderThread:3560 [sender.py:send():375] send: run
2025-06-21 07:19:16,986 INFO    SenderThread:3560 [sender.py:_maybe_setup_resume():761] checking resume status for None/scaling/2gnbqjsi
2025-06-21 07:19:21,983 DEBUG   HandlerThread:3560 [handler.py:handle_request():144] handle_request: keepalive
2025-06-21 07:19:26,993 DEBUG   HandlerThread:3560 [handler.py:handle_request():144] handle_request: keepalive
2025-06-21 07:19:32,002 DEBUG   HandlerThread:3560 [handler.py:handle_request():144] handle_request: keepalive
2025-06-21 07:19:37,005 DEBUG   HandlerThread:3560 [handler.py:handle_request():144] handle_request: keepalive
2025-06-21 07:19:42,010 DEBUG   HandlerThread:3560 [handler.py:handle_request():144] handle_request: keepalive
2025-06-21 07:19:47,012 DEBUG   HandlerThread:3560 [handler.py:handle_request():144] handle_request: keepalive
2025-06-21 07:19:50,634 INFO    SenderThread:3560 [retry.py:__call__():172] Retry attempt failed:
Traceback (most recent call last):
  File "/yinyongjing/anaconda3/envs/smdm/lib/python3.9/site-packages/urllib3/connection.py", line 174, in _new_conn
    conn = connection.create_connection(
  File "/yinyongjing/anaconda3/envs/smdm/lib/python3.9/site-packages/urllib3/util/connection.py", line 95, in create_connection
    raise err
  File "/yinyongjing/anaconda3/envs/smdm/lib/python3.9/site-packages/urllib3/util/connection.py", line 85, in create_connection
    sock.connect(sa)
socket.timeout: timed out

During handling of the above exception, another exception occurred:

Traceback (most recent call last):
  File "/yinyongjing/anaconda3/envs/smdm/lib/python3.9/site-packages/urllib3/connectionpool.py", line 716, in urlopen
    httplib_response = self._make_request(
  File "/yinyongjing/anaconda3/envs/smdm/lib/python3.9/site-packages/urllib3/connectionpool.py", line 404, in _make_request
    self._validate_conn(conn)
  File "/yinyongjing/anaconda3/envs/smdm/lib/python3.9/site-packages/urllib3/connectionpool.py", line 1061, in _validate_conn
    conn.connect()
  File "/yinyongjing/anaconda3/envs/smdm/lib/python3.9/site-packages/urllib3/connection.py", line 363, in connect
    self.sock = conn = self._new_conn()
  File "/yinyongjing/anaconda3/envs/smdm/lib/python3.9/site-packages/urllib3/connection.py", line 179, in _new_conn
    raise ConnectTimeoutError(
urllib3.exceptions.ConnectTimeoutError: (<urllib3.connection.HTTPSConnection object at 0x7fa95dc62be0>, 'Connection to api.wandb.ai timed out. (connect timeout=10)')

During handling of the above exception, another exception occurred:

Traceback (most recent call last):
  File "/yinyongjing/anaconda3/envs/smdm/lib/python3.9/site-packages/requests/adapters.py", line 667, in send
    resp = conn.urlopen(
  File "/yinyongjing/anaconda3/envs/smdm/lib/python3.9/site-packages/urllib3/connectionpool.py", line 802, in urlopen
    retries = retries.increment(
  File "/yinyongjing/anaconda3/envs/smdm/lib/python3.9/site-packages/urllib3/util/retry.py", line 594, in increment
    raise MaxRetryError(_pool, url, error or ResponseError(cause))
urllib3.exceptions.MaxRetryError: HTTPSConnectionPool(host='api.wandb.ai', port=443): Max retries exceeded with url: /graphql (Caused by ConnectTimeoutError(<urllib3.connection.HTTPSConnection object at 0x7fa95dc62be0>, 'Connection to api.wandb.ai timed out. (connect timeout=10)'))

During handling of the above exception, another exception occurred:

Traceback (most recent call last):
  File "/yinyongjing/anaconda3/envs/smdm/lib/python3.9/site-packages/wandb/sdk/lib/retry.py", line 131, in __call__
    result = self._call_fn(*args, **kwargs)
  File "/yinyongjing/anaconda3/envs/smdm/lib/python3.9/site-packages/wandb/sdk/internal/internal_api.py", line 285, in execute
    return self.client.execute(*args, **kwargs)  # type: ignore
  File "/yinyongjing/anaconda3/envs/smdm/lib/python3.9/site-packages/wandb/vendor/gql-0.2.0/wandb_gql/client.py", line 52, in execute
    result = self._get_result(document, *args, **kwargs)
  File "/yinyongjing/anaconda3/envs/smdm/lib/python3.9/site-packages/wandb/vendor/gql-0.2.0/wandb_gql/client.py", line 60, in _get_result
    return self.transport.execute(document, *args, **kwargs)
  File "/yinyongjing/anaconda3/envs/smdm/lib/python3.9/site-packages/wandb/sdk/lib/gql_request.py", line 55, in execute
    request = self.session.post(self.url, **post_args)
  File "/yinyongjing/anaconda3/envs/smdm/lib/python3.9/site-packages/requests/sessions.py", line 637, in post
    return self.request("POST", url, data=data, json=json, **kwargs)
  File "/yinyongjing/anaconda3/envs/smdm/lib/python3.9/site-packages/requests/sessions.py", line 589, in request
    resp = self.send(prep, **send_kwargs)
  File "/yinyongjing/anaconda3/envs/smdm/lib/python3.9/site-packages/requests/sessions.py", line 703, in send
    r = adapter.send(request, **kwargs)
  File "/yinyongjing/anaconda3/envs/smdm/lib/python3.9/site-packages/requests/adapters.py", line 688, in send
    raise ConnectTimeout(e, request=request)
requests.exceptions.ConnectTimeout: HTTPSConnectionPool(host='api.wandb.ai', port=443): Max retries exceeded with url: /graphql (Caused by ConnectTimeoutError(<urllib3.connection.HTTPSConnection object at 0x7fa95dc62be0>, 'Connection to api.wandb.ai timed out. (connect timeout=10)'))
2025-06-21 07:19:52,014 DEBUG   HandlerThread:3560 [handler.py:handle_request():144] handle_request: keepalive
2025-06-21 07:19:57,016 DEBUG   HandlerThread:3560 [handler.py:handle_request():144] handle_request: keepalive
2025-06-21 07:20:02,019 DEBUG   HandlerThread:3560 [handler.py:handle_request():144] handle_request: keepalive
2025-06-21 07:20:07,022 DEBUG   HandlerThread:3560 [handler.py:handle_request():144] handle_request: keepalive
2025-06-21 07:20:12,024 DEBUG   HandlerThread:3560 [handler.py:handle_request():144] handle_request: keepalive
2025-06-21 07:20:17,026 DEBUG   HandlerThread:3560 [handler.py:handle_request():144] handle_request: cancel
2025-06-21 07:20:17,026 DEBUG   HandlerThread:3560 [handler.py:handle_request():144] handle_request: cancel
2025-06-21 07:20:17,741 DEBUG   HandlerThread:3560 [handler.py:handle_request():144] handle_request: shutdown
2025-06-21 07:20:17,741 INFO    HandlerThread:3560 [handler.py:finish():842] shutting down handler
2025-06-21 07:20:18,027 INFO    WriterThread:3560 [datastore.py:close():298] close: workdir/scaling_debug/mdm-170M-10.0/wandb/run-20250621_071916-2gnbqjsi/run-2gnbqjsi.wandb
2025-06-21 07:20:24,602 DEBUG   SenderThread:3560 [sender.py:send():384] Record cancelled: run
2025-06-21 07:20:24,602 INFO    SenderThread:3560 [sender.py:finish():1550] shutting down sender
